Workbook
Name RecCats: 'Player Values - Cats'!$A$2:$I$782
Name RosterS: #REF!
Name AllGProj: #REF!
Name DynCVorpF2: #REF!
Name CheatD: #REF!
Name ADPFHFH: #REF!
Name AllGProjNames: #REF!
Name ADPFantrax: #REF!
Name ProjAGB: #REF!
Name PtsVorpAll: #REF!
Name ProjCull: #REF!
Name CatsPtsUsed: #REF!
Name ProjCullNames: #REF!
Name CatsUsed: #REF!
Name SubtitlePts: #REF!
Name RanksAll: #REF!
Name CleanCatG: #REF!
Name RanksAllCat: #REF!
Name UsedSRCsABV: #REF!
Name PtsVorpG: #REF!
Name FanPtsAll: #REF!
Name ProjYFCats: #REF!
Name GNames: #REF!
Name UsedSRCsWTs: #REF!
Name CleanPtsG: #REF!
Name ProjLXCats: #REF!
Name DNames: #REF!
Name ProjAGN: #REF!
Name TitlePts: #REF!
Name AllProj: #REF!
Name AllProjCats: #REF!
Name CleanPtsD: #REF!
Name ProjDtZCats: #REF!
Name ProjSLCats: #REF!
Name SubtitleCats: #REF!
Name ValsAll: 'Player Values - Cats'!$E$2:$H$782
Name ProjSL: #REF!
Name ProjDFONames: #REF!
Name ProjCullCats: #REF!
Name Proji2Names: #REF!
Name ProjESPNCats: #REF!
Name ProjDtZ: #REF!
Name UsedSRCs: #REF!
Name SNames: #REF!
Name NamesMasterList: #REF!
Name fixnames: #REF!
Name ProjAGNNames: #REF!
Name ProjKUBNames: #REF!
Name RecPoints: #REF!
Name TeamPOS: #REF!
Name CleanCatHeaderG: #REF!
Name FNames: #REF!
Name AllProjStdev: #REF!
Name CleanPtsHeaderG: #REF!
Name CleanPtsHeaderF: #REF!
Name RanksAllNames: #REF!
Name ProjESPN: #REF!
Name ProjAGBNames: #REF!
Name VorpG: #REF!
Name RosterT: #REF!

Sheet Roster Comparison
A1: Top skaters: | B1: 10 | F1: Projections: | G1: 1
A2: Top goalies: | B2: 1 | F2: Stats (Season): | G2: 0
F3: Stats (Last 2 weeks): | G3: 0
R4: ="(top " & $B1 & ")" -> (top 10) | AB4: ="(top " & $B2 & ")" -> (top 1)
A5: Teams | B5: G | C5: A | D5: +/- | E5: PIM | F5: PPP | G5: SHP | H5: SOG | I5: FOW | J5: HIT | K5: BLK | L5: W | M5: GAA | N5: SV% | O5: SO | R5: =B5 -> G | S5: =C5 -> A | T5: =D5 -> +/- | U5: =E5 -> PIM | V5: =F5 -> PPP | W5: =G5 -> SHP | X5: =H5 -> SOG | Y5: =I5 -> FOW | ... AE5: =O5 -> SO
A6: Rob/Orad | B6: =AVERAGEIFS('Player Values - Cats'!O:O, 'Player Values - Cats'!$D:$D, $A6, 'Player Values - Cats'!O:O, "<>") -> 0.327952 | C6: =AVERAGEIFS('Player Values - Cats'!P:P, 'Player Values - Cats'!$D:$D, $A6, 'Player Values - Cats'!P:P, "<>") -> 0.45132497 | D6: =AVERAGEIFS('Player Values - Cats'!Q:Q, 'Player Values - Cats'!$D:$D, $A6, 'Player Values - Cats'!Q:Q, "<>") -> -0.21972986 | E6: =AVERAGEIFS('Player Values - Cats'!R:R, 'Player Values - Cats'!$D:$D, $A6, 'Player Values - Cats'!R:R, "<>") -> -0.66253943 | F6: =AVERAGEIFS('Player Values - Cats'!S:S, 'Player Values - Cats'!$D:$D, $A6, 'Player Values - Cats'!S:S, "<>") -> 0.49238204 | G6: =AVERAGEIFS('Player Values - Cats'!T:T, 'Player Values - Cats'!$D:$D, $A6, 'Player Values - Cats'!T:T, "<>") -> -0.28343632 | H6: =AVERAGEIFS('Player Values - Cats'!U:U, 'Player Values - Cats'!$D:$D, $A6, 'Player Values - Cats'!U:U, "<>") -> 0.42202079 | I6: =AVERAGEIFS('Player Values - Cats'!V:V, 'Player Values - Cats'!$D:$D, $A6, 'Player Values - Cats'!V:V, "<>") -> 0.44924446 | J6: =AVERAGEIFS('Player Values - Cats'!W:W, 'Player Values - Cats'!$D:$D, $A6, 'Player Values - Cats'!W:W, "<>") -> -1.0610389 | K6: =AVERAGEIFS('Player Values - Cats'!X:X, 'Player Values - Cats'!$D:$D, $A6, 'Player Values - Cats'!X:X, "<>") -> -0.67174887 | L6: =AVERAGEIFS('Player Values - Cats'!Y:Y, 'Player Values - Cats'!$D:$D, $A6, 'Player Values - Cats'!Y:Y, "<>") -> 0.14827394 | M6: =AVERAGEIFS('Player Values - Cats'!Z:Z, 'Player Values - Cats'!$D:$D, $A6, 'Player Values - Cats'!Z:Z, "<>") -> 0.48429728 | N6: =AVERAGEIFS('Player Values - Cats'!AA:AA, 'Player Values - Cats'!$D:$D, $A6, 'Player Values - Cats'!AA:AA, "<>") -> 0.76181425 | O6: =AVERAGEIFS('Player Values - Cats'!AB:AB, 'Player Values - Cats'!$D:$D, $A6, 'Player Values - Cats'!AB:AB, "<>") -> 0.28765514 | R6: =IFERROR(__xludf.DUMMYFUNCTION("AVERAGE(SORTN(FILTER('Player Values - Cats'!O4:O1004, 'Player Values - Cats'!$D4:$D1004 = $A6, ISNUMBER('Player Values - Cats'!O4:O1004)), $B$1, 0, 1, FALSE))"),1.8976392830899713) -> 1.8976393 | S6: =IFERROR(__xludf.DUMMYFUNCTION("AVERAGE(SORTN(FILTER('Player Values - Cats'!P4:P1004, 'Player Values - Cats'!$D4:$D1004 = $A6, ISNUMBER('Player Values - Cats'!P4:P1004)), $B$1, 0, 1, FALSE))"),1.3492117614141554) -> 1.3492118 | T6: =IFERROR(__xludf.DUMMYFUNCTION("AVERAGE(SORTN(FILTER('Player Values - Cats'!Q4:Q1004, 'Player Values - Cats'!$D4:$D1004 = $A6, ISNUMBER('Player Values - Cats'!Q4:Q1004)), $B$1, 0, 1, FALSE))"),1.3585673638811517) -> 1.3585674 | U6: =IFERROR(__xludf.DUMMYFUNCTION("AVERAGE(SORTN(FILTER('Player Values - Cats'!R4:R1004, 'Player Values - Cats'!$D4:$D1004 = $A6, ISNUMBER('Player Values - Cats'!R4:R1004)), $B$1, 0, 1, FALSE))"),0.09998580362168116) -> 0.099985804 | V6: =IFERROR(__xludf.DUMMYFUNCTION("AVERAGE(SORTN(FILTER('Player Values - Cats'!S4:S1004, 'Player Values - Cats'!$D4:$D1004 = $A6, ISNUMBER('Player Values - Cats'!S4:S1004)), $B$1, 0, 1, FALSE))"),1.585957783140048) -> 1.5859578 | W6: =IFERROR(__xludf.DUMMYFUNCTION("AVERAGE(SORTN(FILTER('Player Values - Cats'!T4:T1004, 'Player Values - Cats'!$D4:$D1004 = $A6, ISNUMBER('Player Values - Cats'!T4:T1004)), $B$1, 0, 1, FALSE))"),0.3061020155722415) -> 0.30610202 | X6: =IFERROR(__xludf.DUMMYFUNCTION("AVERAGE(SORTN(FILTER('Player Values - Cats'!U4:U1004, 'Player Values - Cats'!$D4:$D1004 = $A6, ISNUMBER('Player Values - Cats'!U4:U1004)), $B$1, 0, 1, FALSE))"),1.73308554964389) -> 1.7330855 | Y6: =IFERROR(__xludf.DUMMYFUNCTION("AVERAGE(SORTN(FILTER('Player Values - Cats'!V4:V1004, 'Player Values - Cats'!$D4:$D1004 = $A6, ISNUMBER('Player Values - Cats'!V4:V1004)), $B$1, 0, 1, FALSE))"),1.2578844900313255) -> 1.2578845 | Z6: =IFERROR(__xludf.DUMMYFUNCTION("AVERAGE(SORTN(FILTER('Player Values - Cats'!W4:W1004, 'Player Values - Cats'!$D4:$D1004 = $A6, ISNUMBER('Player Values - Cats'!W4:W1004)), $B$1, 0, 1, FALSE))"),0.12338765731894183) -> 0.12338766 | AA6: =IFERROR(__xludf.DUMMYFUNCTION("AVERAGE(SORTN(FILTER('Player Values - Cats'!X4:X1004, 'Player Values - Cats'!$D4:$D1004 = $A6, ISNUMBER('Player Values - Cats'!X4:X1004)), $B$1, 0, 1, FALSE))"),0.6989707987977977) -> 0.6989708 | AB6: =IFERROR(__xludf.DUMMYFUNCTION("AVERAGE(SORTN(FILTER('Player Values - Cats'!Y4:Y1004, 'Player Values - Cats'!$D4:$D1004 = $A6, ISNUMBER('Player Values - Cats'!Y4:Y1004)), $B$2, 0, 1, FALSE))"),1.0053222056340791) -> 1.0053222 | AC6: =IFERROR(__xludf.DUMMYFUNCTION("AVERAGE(SORTN(FILTER('Player Values - Cats'!Z4:Z1004, 'Player Values - Cats'!$D4:$D1004 = $A6, ISNUMBER('Player Values - Cats'!Z4:Z1004)), $B$2, 0, 1, FALSE))"),1.3687519183327665) -> 1.3687519 | AD6: =IFERROR(__xludf.DUMMYFUNCTION("AVERAGE(SORTN(FILTER('Player Values - Cats'!AA4:AA1004, 'Player Values - Cats'!$D4:$D1004 = $A6, ISNUMBER('Player Values - Cats'!AA4:AA1004)), $B$2, 0, 1, FALSE))"),1.5200976887423285) -> 1.5200977 | AE6: =IFERROR(__xludf.DUMMYFUNCTION("AVERAGE(SORTN(FILTER('Player Values - Cats'!AB4:AB1004, 'Player Values - Cats'!$D4:$D1004 = $A6, ISNUMBER('Player Values - Cats'!AB4:AB1004)), $B$2, 0, 1, FALSE))"),0.5595319820068041) -> 0.55953198
A7: Phil | B7: =AVERAGEIFS('Player Values - Cats'!O:O, 'Player Values - Cats'!$D:$D, $A7, 'Player Values - Cats'!O:O, "<>") -> 0.20498198 | C7: =AVERAGEIFS('Player Values - Cats'!P:P, 'Player Values - Cats'!$D:$D, $A7, 'Player Values - Cats'!P:P, "<>") -> 0.35212339 | D7: =AVERAGEIFS('Player Values - Cats'!Q:Q, 'Player Values - Cats'!$D:$D, $A7, 'Player Values - Cats'!Q:Q, "<>") -> -0.89578246 | E7: =AVERAGEIFS('Player Values - Cats'!R:R, 'Player Values - Cats'!$D:$D, $A7, 'Player Values - Cats'!R:R, "<>") -> -0.7951115 | F7: =AVERAGEIFS('Player Values - Cats'!S:S, 'Player Values - Cats'!$D:$D, $A7, 'Player Values - Cats'!S:S, "<>") -> 0.45402565 | G7: =AVERAGEIFS('Player Values - Cats'!T:T, 'Player Values - Cats'!$D:$D, $A7, 'Player Values - Cats'!T:T, "<>") -> -0.37504595 | H7: =AVERAGEIFS('Player Values - Cats'!U:U, 'Player Values - Cats'!$D:$D, $A7, 'Player Values - Cats'!U:U, "<>") -> 0.54175657 | I7: =AVERAGEIFS('Player Values - Cats'!V:V, 'Player Values - Cats'!$D:$D, $A7, 'Player Values - Cats'!V:V, "<>") -> 0.53525096 | J7: =AVERAGEIFS('Player Values - Cats'!W:W, 'Player Values - Cats'!$D:$D, $A7, 'Player Values - Cats'!W:W, "<>") -> -1.1198281 | K7: =AVERAGEIFS('Player Values - Cats'!X:X, 'Player Values - Cats'!$D:$D, $A7, 'Player Values - Cats'!X:X, "<>") -> -0.61222849 | L7: =AVERAGEIFS('Player Values - Cats'!Y:Y, 'Player Values - Cats'!$D:$D, $A7, 'Player Values - Cats'!Y:Y, "<>") -> -0.22893941 | M7: =AVERAGEIFS('Player Values - Cats'!Z:Z, 'Player Values - Cats'!$D:$D, $A7, 'Player Values - Cats'!Z:Z, "<>") -> 0.21131746 | N7: =AVERAGEIFS('Player Values - Cats'!AA:AA, 'Player Values - Cats'!$D:$D, $A7, 'Player Values - Cats'!AA:AA, "<>") -> -1.1338943 | O7: =AVERAGEIFS('Player Values - Cats'!AB:AB, 'Player Values - Cats'!$D:$D, $A7, 'Player Values - Cats'!AB:AB, "<>") -> 0.04532735 | R7: =IFERROR(__xludf.DUMMYFUNCTION("AVERAGE(SORTN(FILTER('Player Values - Cats'!O2:O1004, 'Player Values - Cats'!$D2:$D1004 = $A7, ISNUMBER('Player Values - Cats'!O2:O1004)), $B$1, 0, 1, FALSE))"),1.5283064857408868) -> 1.5283065 | S7: =IFERROR(__xludf.DUMMYFUNCTION("AVERAGE(SORTN(FILTER('Player Values - Cats'!P2:P1004, 'Player Values - Cats'!$D2:$D1004 = $A7, ISNUMBER('Player Values - Cats'!P2:P1004)), $B$1, 0, 1, FALSE))"),1.3508502889238034) -> 1.3508503 | T7: =IFERROR(__xludf.DUMMYFUNCTION("AVERAGE(SORTN(FILTER('Player Values - Cats'!Q2:Q1004, 'Player Values - Cats'!$D2:$D1004 = $A7, ISNUMBER('Player Values - Cats'!Q2:Q1004)), $B$1, 0, 1, FALSE))"),0.913027557192971) -> 0.91302756 | U7: =IFERROR(__xludf.DUMMYFUNCTION("AVERAGE(SORTN(FILTER('Player Values - Cats'!R2:R1004, 'Player Values - Cats'!$D2:$D1004 = $A7, ISNUMBER('Player Values - Cats'!R2:R1004)), $B$1, 0, 1, FALSE))"),0.10283221437667889) -> 0.10283221 | V7: =IFERROR(__xludf.DUMMYFUNCTION("AVERAGE(SORTN(FILTER('Player Values - Cats'!S2:S1004, 'Player Values - Cats'!$D2:$D1004 = $A7, ISNUMBER('Player Values - Cats'!S2:S1004)), $B$1, 0, 1, FALSE))"),1.5399335739963325) -> 1.5399336 | W7: =IFERROR(__xludf.DUMMYFUNCTION("AVERAGE(SORTN(FILTER('Player Values - Cats'!T2:T1004, 'Player Values - Cats'!$D2:$D1004 = $A7, ISNUMBER('Player Values - Cats'!T2:T1004)), $B$1, 0, 1, FALSE))"),0.2142399106252011) -> 0.21423991 | X7: =IFERROR(__xludf.DUMMYFUNCTION("AVERAGE(SORTN(FILTER('Player Values - Cats'!U2:U1004, 'Player Values - Cats'!$D2:$D1004 = $A7, ISNUMBER('Player Values - Cats'!U2:U1004)), $B$1, 0, 1, FALSE))"),1.769588854469309) -> 1.7695889 | Y7: =IFERROR(__xludf.DUMMYFUNCTION("AVERAGE(SORTN(FILTER('Player Values - Cats'!V2:V1004, 'Player Values - Cats'!$D2:$D1004 = $A7, ISNUMBER('Player Values - Cats'!V2:V1004)), $B$1, 0, 1, FALSE))"),1.3916524955446237) -> 1.3916525 | Z7: =IFERROR(__xludf.DUMMYFUNCTION("AVERAGE(SORTN(FILTER('Player Values - Cats'!W2:W1004, 'Player Values - Cats'!$D2:$D1004 = $A7, ISNUMBER('Player Values - Cats'!W2:W1004)), $B$1, 0, 1, FALSE))"),-0.3804648441124671) -> -0.38046484 | AA7: =IFERROR(__xludf.DUMMYFUNCTION("AVERAGE(SORTN(FILTER('Player Values - Cats'!X2:X1004, 'Player Values - Cats'!$D2:$D1004 = $A7, ISNUMBER('Player Values - Cats'!X2:X1004)), $B$1, 0, 1, FALSE))"),0.7376908232470947) -> 0.73769082 | AB7: =IFERROR(__xludf.DUMMYFUNCTION("AVERAGE(SORTN(FILTER('Player Values - Cats'!Y2:Y1004, 'Player Values - Cats'!$D2:$D1004 = $A7, ISNUMBER('Player Values - Cats'!Y2:Y1004)), $B$2, 0, 1, FALSE))"),1.2331986708569582) -> 1.2331987 | AC7: =IFERROR(__xludf.DUMMYFUNCTION("AVERAGE(SORTN(FILTER('Player Values - Cats'!Z2:Z1004, 'Player Values - Cats'!$D2:$D1004 = $A7, ISNUMBER('Player Values - Cats'!Z2:Z1004)), $B$2, 0, 1, FALSE))"),0.6553646397745425) -> 0.65536464 | AD7: =IFERROR(__xludf.DUMMYFUNCTION("AVERAGE(SORTN(FILTER('Player Values - Cats'!AA2:AA1004, 'Player Values - Cats'!$D2:$D1004 = $A7, ISNUMBER('Player Values - Cats'!AA2:AA1004)), $B$2, 0, 1, FALSE))"),-0.3825043957404056) -> -0.3825044 | AE7: =IFERROR(__xludf.DUMMYFUNCTION("AVERAGE(SORTN(FILTER('Player Values - Cats'!AB2:AB1004, 'Player Values - Cats'!$D2:$D1004 = $A7, ISNUMBER('Player Values - Cats'!AB2:AB1004)), $B$2, 0, 1, FALSE))"),0.130246657537567) -> 0.13024666
A8: Ilan | B8: =AVERAGEIFS('Player Values - Cats'!O:O, 'Player Values - Cats'!$D:$D, $A8, 'Player Values - Cats'!O:O, "<>") -> 0.20732227 | C8: =AVERAGEIFS('Player Values - Cats'!P:P, 'Player Values - Cats'!$D:$D, $A8, 'Player Values - Cats'!P:P, "<>") -> 0.42218843 | D8: =AVERAGEIFS('Player Values - Cats'!Q:Q, 'Player Values - Cats'!$D:$D, $A8, 'Player Values - Cats'!Q:Q, "<>") -> -0.46366952 | E8: =AVERAGEIFS('Player Values - Cats'!R:R, 'Player Values - Cats'!$D:$D, $A8, 'Player Values - Cats'!R:R, "<>") -> -0.34168553 | F8: =AVERAGEIFS('Player Values - Cats'!S:S, 'Player Values - Cats'!$D:$D, $A8, 'Player Values - Cats'!S:S, "<>") -> 0.27643363 | G8: =AVERAGEIFS('Player Values - Cats'!T:T, 'Player Values - Cats'!$D:$D, $A8, 'Player Values - Cats'!T:T, "<>") -> -0.26951872 | H8: =AVERAGEIFS('Player Values - Cats'!U:U, 'Player Values - Cats'!$D:$D, $A8, 'Player Values - Cats'!U:U, "<>") -> 0.44216653 | I8: =AVERAGEIFS('Player Values - Cats'!V:V, 'Player Values - Cats'!$D:$D, $A8, 'Player Values - Cats'!V:V, "<>") -> 0.42556485 | J8: =AVERAGEIFS('Player Values - Cats'!W:W, 'Player Values - Cats'!$D:$D, $A8, 'Player Values - Cats'!W:W, "<>") -> -1.0838902 | K8: =AVERAGEIFS('Player Values - Cats'!X:X, 'Player Values - Cats'!$D:$D, $A8, 'Player Values - Cats'!X:X, "<>") -> -0.7945941 | L8: =AVERAGEIFS('Player Values - Cats'!Y:Y, 'Player Values - Cats'!$D:$D, $A8, 'Player Values - Cats'!Y:Y, "<>") -> -0.057640899 | M8: =AVERAGEIFS('Player Values - Cats'!Z:Z, 'Player Values - Cats'!$D:$D, $A8, 'Player Values - Cats'!Z:Z, "<>") -> -1.4411204 | N8: =AVERAGEIFS('Player Values - Cats'!AA:AA, 'Player Values - Cats'!$D:$D, $A8, 'Player Values - Cats'!AA:AA, "<>") -> -0.66375862 | O8: =AVERAGEIFS('Player Values - Cats'!AB:AB, 'Player Values - Cats'!$D:$D, $A8, 'Player Values - Cats'!AB:AB, "<>") -> 0.20450064 | R8: =IFERROR(__xludf.DUMMYFUNCTION("AVERAGE(SORTN(FILTER('Player Values - Cats'!O9:O1004, 'Player Values - Cats'!$D9:$D1004 = $A8, ISNUMBER('Player Values - Cats'!O9:O1004)), $B$1, 0, 1, FALSE))"),1.3293865258551159) -> 1.3293865 | S8: =IFERROR(__xludf.DUMMYFUNCTION("AVERAGE(SORTN(FILTER('Player Values - Cats'!P9:P1004, 'Player Values - Cats'!$D9:$D1004 = $A8, ISNUMBER('Player Values - Cats'!P9:P1004)), $B$1, 0, 1, FALSE))"),1.3826742302562587) -> 1.3826742 | T8: =IFERROR(__xludf.DUMMYFUNCTION("AVERAGE(SORTN(FILTER('Player Values - Cats'!Q9:Q1004, 'Player Values - Cats'!$D9:$D1004 = $A8, ISNUMBER('Player Values - Cats'!Q9:Q1004)), $B$1, 0, 1, FALSE))"),0.6198454536311508) -> 0.61984545 | U8: =IFERROR(__xludf.DUMMYFUNCTION("AVERAGE(SORTN(FILTER('Player Values - Cats'!R9:R1004, 'Player Values - Cats'!$D9:$D1004 = $A8, ISNUMBER('Player Values - Cats'!R9:R1004)), $B$1, 0, 1, FALSE))"),0.741762515018441) -> 0.74176252 | V8: =IFERROR(__xludf.DUMMYFUNCTION("AVERAGE(SORTN(FILTER('Player Values - Cats'!S9:S1004, 'Player Values - Cats'!$D9:$D1004 = $A8, ISNUMBER('Player Values - Cats'!S9:S1004)), $B$1, 0, 1, FALSE))"),1.206226252905497) -> 1.2062263 | W8: =IFERROR(__xludf.DUMMYFUNCTION("AVERAGE(SORTN(FILTER('Player Values - Cats'!T9:T1004, 'Player Values - Cats'!$D9:$D1004 = $A8, ISNUMBER('Player Values - Cats'!T9:T1004)), $B$1, 0, 1, FALSE))"),0.2952061496015803) -> 0.29520615 | X8: =IFERROR(__xludf.DUMMYFUNCTION("AVERAGE(SORTN(FILTER('Player Values - Cats'!U9:U1004, 'Player Values - Cats'!$D9:$D1004 = $A8, ISNUMBER('Player Values - Cats'!U9:U1004)), $B$1, 0, 1, FALSE))"),1.2390467921752375) -> 1.2390468 | Y8: =IFERROR(__xludf.DUMMYFUNCTION("AVERAGE(SORTN(FILTER('Player Values - Cats'!V9:V1004, 'Player Values - Cats'!$D9:$D1004 = $A8, ISNUMBER('Player Values - Cats'!V9:V1004)), $B$1, 0, 1, FALSE))"),1.1490250867141936) -> 1.1490251 | Z8: =IFERROR(__xludf.DUMMYFUNCTION("AVERAGE(SORTN(FILTER('Player Values - Cats'!W9:W1004, 'Player Values - Cats'!$D9:$D1004 = $A8, ISNUMBER('Player Values - Cats'!W9:W1004)), $B$1, 0, 1, FALSE))"),-0.2623597062602026) -> -0.26235971 | AA8: =IFERROR(__xludf.DUMMYFUNCTION("AVERAGE(SORTN(FILTER('Player Values - Cats'!X9:X1004, 'Player Values - Cats'!$D9:$D1004 = $A8, ISNUMBER('Player Values - Cats'!X9:X1004)), $B$1, 0, 1, FALSE))"),0.6472660485088325) -> 0.64726605 | AB8: =IFERROR(__xludf.DUMMYFUNCTION("AVERAGE(SORTN(FILTER('Player Values - Cats'!Y9:Y1004, 'Player Values - Cats'!$D9:$D1004 = $A8, ISNUMBER('Player Values - Cats'!Y9:Y1004)), $B$2, 0, 1, FALSE))"),0.823392231031477) -> 0.82339223 | AC8: =IFERROR(__xludf.DUMMYFUNCTION("AVERAGE(SORTN(FILTER('Player Values - Cats'!Z9:Z1004, 'Player Values - Cats'!$D9:$D1004 = $A8, ISNUMBER('Player Values - Cats'!Z9:Z1004)), $B$2, 0, 1, FALSE))"),0.5534521714090794) -> 0.55345217 | AD8: =IFERROR(__xludf.DUMMYFUNCTION("AVERAGE(SORTN(FILTER('Player Values - Cats'!AA9:AA1004, 'Player Values - Cats'!$D9:$D1004 = $A8, ISNUMBER('Player Values - Cats'!AA9:AA1004)), $B$2, 0, 1, FALSE))"),0.9410448804215005) -> 0.94104488 | AE8: =IFERROR(__xludf.DUMMYFUNCTION("AVERAGE(SORTN(FILTER('Player Values - Cats'!AB9:AB1004, 'Player Values - Cats'!$D9:$D1004 = $A8, ISNUMBER('Player Values - Cats'!AB9:AB1004)), $B$2, 0, 1, FALSE))"),0.5332818990797707) -> 0.5332819
A9: Lev | B9: =AVERAGEIFS('Player Values - Cats'!O:O, 'Player Values - Cats'!$D:$D, $A9, 'Player Values - Cats'!O:O, "<>") -> 0.22145803 | C9: =AVERAGEIFS('Player Values - Cats'!P:P, 'Player Values - Cats'!$D:$D, $A9, 'Player Values - Cats'!P:P, "<>") -> 0.53909584 | D9: =AVERAGEIFS('Player Values - Cats'!Q:Q, 'Player Values - Cats'!$D:$D, $A9, 'Player Values - Cats'!Q:Q, "<>") -> -0.20617879 | E9: =AVERAGEIFS('Player Values - Cats'!R:R, 'Player Values - Cats'!$D:$D, $A9, 'Player Values - Cats'!R:R, "<>") -> -0.85465096 | F9: =AVERAGEIFS('Player Values - Cats'!S:S, 'Player Values - Cats'!$D:$D, $A9, 'Player Values - Cats'!S:S, "<>") -> 0.51447816 | G9: =AVERAGEIFS('Player Values - Cats'!T:T, 'Player Values - Cats'!$D:$D, $A9, 'Player Values - Cats'!T:T, "<>") -> -0.31131348 | H9: =AVERAGEIFS('Player Values - Cats'!U:U, 'Player Values - Cats'!$D:$D, $A9, 'Player Values - Cats'!U:U, "<>") -> 0.24940123 | I9: =AVERAGEIFS('Player Values - Cats'!V:V, 'Player Values - Cats'!$D:$D, $A9, 'Player Values - Cats'!V:V, "<>") -> 0.39160964 | J9: =AVERAGEIFS('Player Values - Cats'!W:W, 'Player Values - Cats'!$D:$D, $A9, 'Player Values - Cats'!W:W, "<>") -> -1.1576657 | K9: =AVERAGEIFS('Player Values - Cats'!X:X, 'Player Values - Cats'!$D:$D, $A9, 'Player Values - Cats'!X:X, "<>") -> -0.81234019 | L9: =AVERAGEIFS('Player Values - Cats'!Y:Y, 'Player Values - Cats'!$D:$D, $A9, 'Player Values - Cats'!Y:Y, "<>") -> -0.29804528 | M9: =AVERAGEIFS('Player Values - Cats'!Z:Z, 'Player Values - Cats'!$D:$D, $A9, 'Player Values - Cats'!Z:Z, "<>") -> -0.44674591 | N9: =AVERAGEIFS('Player Values - Cats'!AA:AA, 'Player Values - Cats'!$D:$D, $A9, 'Player Values - Cats'!AA:AA, "<>") -> 0.0069775527 | O9: =AVERAGEIFS('Player Values - Cats'!AB:AB, 'Player Values - Cats'!$D:$D, $A9, 'Player Values - Cats'!AB:AB, "<>") -> 0.13243987 | R9: =IFERROR(__xludf.DUMMYFUNCTION("AVERAGE(SORTN(FILTER('Player Values - Cats'!O10:O1004, 'Player Values - Cats'!$D10:$D1004 = $A9, ISNUMBER('Player Values - Cats'!O10:O1004)), $B$1, 0, 1, FALSE))"),1.0940676050410412) -> 1.0940676 | S9: =IFERROR(__xludf.DUMMYFUNCTION("AVERAGE(SORTN(FILTER('Player Values - Cats'!P10:P1004, 'Player Values - Cats'!$D10:$D1004 = $A9, ISNUMBER('Player Values - Cats'!P10:P1004)), $B$1, 0, 1, FALSE))"),1.1492969957342418) -> 1.149297 | T9: =IFERROR(__xludf.DUMMYFUNCTION("AVERAGE(SORTN(FILTER('Player Values - Cats'!Q10:Q1004, 'Player Values - Cats'!$D10:$D1004 = $A9, ISNUMBER('Player Values - Cats'!Q10:Q1004)), $B$1, 0, 1, FALSE))"),1.009112817714476) -> 1.0091128 | U9: =IFERROR(__xludf.DUMMYFUNCTION("AVERAGE(SORTN(FILTER('Player Values - Cats'!R10:R1004, 'Player Values - Cats'!$D10:$D1004 = $A9, ISNUMBER('Player Values - Cats'!R10:R1004)), $B$1, 0, 1, FALSE))"),-0.2027231649730597) -> -0.20272317 | V9: =IFERROR(__xludf.DUMMYFUNCTION("AVERAGE(SORTN(FILTER('Player Values - Cats'!S10:S1004, 'Player Values - Cats'!$D10:$D1004 = $A9, ISNUMBER('Player Values - Cats'!S10:S1004)), $B$1, 0, 1, FALSE))"),1.1749769139592012) -> 1.1749769 | W9: =IFERROR(__xludf.DUMMYFUNCTION("AVERAGE(SORTN(FILTER('Player Values - Cats'!T10:T1004, 'Player Values - Cats'!$D10:$D1004 = $A9, ISNUMBER('Player Values - Cats'!T10:T1004)), $B$1, 0, 1, FALSE))"),0.3428881262712196) -> 0.34288813 | X9: =IFERROR(__xludf.DUMMYFUNCTION("AVERAGE(SORTN(FILTER('Player Values - Cats'!U10:U1004, 'Player Values - Cats'!$D10:$D1004 = $A9, ISNUMBER('Player Values - Cats'!U10:U1004)), $B$1, 0, 1, FALSE))"),0.9036046514834648) -> 0.90360465 | Y9: =IFERROR(__xludf.DUMMYFUNCTION("AVERAGE(SORTN(FILTER('Player Values - Cats'!V10:V1004, 'Player Values - Cats'!$D10:$D1004 = $A9, ISNUMBER('Player Values - Cats'!V10:V1004)), $B$1, 0, 1, FALSE))"),0.7396404491192615) -> 0.73964045 | Z9: =IFERROR(__xludf.DUMMYFUNCTION("AVERAGE(SORTN(FILTER('Player Values - Cats'!W10:W1004, 'Player Values - Cats'!$D10:$D1004 = $A9, ISNUMBER('Player Values - Cats'!W10:W1004)), $B$1, 0, 1, FALSE))"),-0.23060246974440188) -> -0.23060247 | AA9: =IFERROR(__xludf.DUMMYFUNCTION("AVERAGE(SORTN(FILTER('Player Values - Cats'!X10:X1004, 'Player Values - Cats'!$D10:$D1004 = $A9, ISNUMBER('Player Values - Cats'!X10:X1004)), $B$1, 0, 1, FALSE))"),0.6043449887905302) -> 0.60434499 | AB9: =IFERROR(__xludf.DUMMYFUNCTION("AVERAGE(SORTN(FILTER('Player Values - Cats'!Y10:Y1004, 'Player Values - Cats'!$D10:$D1004 = $A9, ISNUMBER('Player Values - Cats'!Y10:Y1004)), $B$2, 0, 1, FALSE))"),2.263725149771413) -> 2.2637251 | AC9: =IFERROR(__xludf.DUMMYFUNCTION("AVERAGE(SORTN(FILTER('Player Values - Cats'!Z10:Z1004, 'Player Values - Cats'!$D10:$D1004 = $A9, ISNUMBER('Player Values - Cats'!Z10:Z1004)), $B$2, 0, 1, FALSE))"),1.892873184212281) -> 1.8928732 | AD9: =IFERROR(__xludf.DUMMYFUNCTION("AVERAGE(SORTN(FILTER('Player Values - Cats'!AA10:AA1004, 'Player Values - Cats'!$D10:$D1004 = $A9, ISNUMBER('Player Values - Cats'!AA10:AA1004)), $B$2, 0, 1, FALSE))"),1.464949802235589) -> 1.4649498 | AE9: =IFERROR(__xludf.DUMMYFUNCTION("AVERAGE(SORTN(FILTER('Player Values - Cats'!AB10:AB1004, 'Player Values - Cats'!$D10:$D1004 = $A9, ISNUMBER('Player Values - Cats'!AB10:AB1004)), $B$2, 0, 1, FALSE))"),0.5297594671832909) -> 0.52975947
A10: Henry | B10: =AVERAGEIFS('Player Values - Cats'!O:O, 'Player Values - Cats'!$D:$D, $A10, 'Player Values - Cats'!O:O, "<>") -> 0.06352854 | C10: =AVERAGEIFS('Player Values - Cats'!P:P, 'Player Values - Cats'!$D:$D, $A10, 'Player Values - Cats'!P:P, "<>") -> 0.075267703 | D10: =AVERAGEIFS('Player Values - Cats'!Q:Q, 'Player Values - Cats'!$D:$D, $A10, 'Player Values - Cats'!Q:Q, "<>") -> -0.5455852 | E10: =AVERAGEIFS('Player Values - Cats'!R:R, 'Player Values - Cats'!$D:$D, $A10, 'Player Values - Cats'!R:R, "<>") -> -0.51799118 | F10: =AVERAGEIFS('Player Values - Cats'!S:S, 'Player Values - Cats'!$D:$D, $A10, 'Player Values - Cats'!S:S, "<>") -> -0.022837537 | G10: =AVERAGEIFS('Player Values - Cats'!T:T, 'Player Values - Cats'!$D:$D, $A10, 'Player Values - Cats'!T:T, "<>") -> -0.32105145 | H10: =AVERAGEIFS('Player Values - Cats'!U:U, 'Player Values - Cats'!$D:$D, $A10, 'Player Values - Cats'!U:U, "<>") -> 0.35716249 | I10: =AVERAGEIFS('Player Values - Cats'!V:V, 'Player Values - Cats'!$D:$D, $A10, 'Player Values - Cats'!V:V, "<>") -> 0.3182132 | J10: =AVERAGEIFS('Player Values - Cats'!W:W, 'Player Values - Cats'!$D:$D, $A10, 'Player Values - Cats'!W:W, "<>") -> -0.72922343 | K10: =AVERAGEIFS('Player Values - Cats'!X:X, 'Player Values - Cats'!$D:$D, $A10, 'Player Values - Cats'!X:X, "<>") -> -0.74499471 | L10: =AVERAGEIFS('Player Values - Cats'!Y:Y, 'Player Values - Cats'!$D:$D, $A10, 'Player Values - Cats'!Y:Y, "<>") -> -0.33620499 | M10: =AVERAGEIFS('Player Values - Cats'!Z:Z, 'Player Values - Cats'!$D:$D, $A10, 'Player Values - Cats'!Z:Z, "<>") -> -0.20433983 | N10: =AVERAGEIFS('Player Values - Cats'!AA:AA, 'Player Values - Cats'!$D:$D, $A10, 'Player Values - Cats'!AA:AA, "<>") -> -1.0563426 | O10: =AVERAGEIFS('Player Values - Cats'!AB:AB, 'Player Values - Cats'!$D:$D, $A10, 'Player Values - Cats'!AB:AB, "<>") -> 0.13385592 | R10: =IFERROR(__xludf.DUMMYFUNCTION("AVERAGE(SORTN(FILTER('Player Values - Cats'!O11:O1004, 'Player Values - Cats'!$D11:$D1004 = $A10, ISNUMBER('Player Values - Cats'!O11:O1004)), $B$1, 0, 1, FALSE))"),1.2862300474356254) -> 1.28623 | S10: =IFERROR(__xludf.DUMMYFUNCTION("AVERAGE(SORTN(FILTER('Player Values - Cats'!P11:P1004, 'Player Values - Cats'!$D11:$D1004 = $A10, ISNUMBER('Player Values - Cats'!P11:P1004)), $B$1, 0, 1, FALSE))"),0.7964542762615459) -> 0.79645428 | T10: =IFERROR(__xludf.DUMMYFUNCTION("AVERAGE(SORTN(FILTER('Player Values - Cats'!Q11:Q1004, 'Player Values - Cats'!$D11:$D1004 = $A10, ISNUMBER('Player Values - Cats'!Q11:Q1004)), $B$1, 0, 1, FALSE))"),0.5396269345905705) -> 0.53962693 | U10: =IFERROR(__xludf.DUMMYFUNCTION("AVERAGE(SORTN(FILTER('Player Values - Cats'!R11:R1004, 'Player Values - Cats'!$D11:$D1004 = $A10, ISNUMBER('Player Values - Cats'!R11:R1004)), $B$1, 0, 1, FALSE))"),0.9377724169583175) -> 0.93777242 | V10: =IFERROR(__xludf.DUMMYFUNCTION("AVERAGE(SORTN(FILTER('Player Values - Cats'!S11:S1004, 'Player Values - Cats'!$D11:$D1004 = $A10, ISNUMBER('Player Values - Cats'!S11:S1004)), $B$1, 0, 1, FALSE))"),0.9147521294407579) -> 0.91475213 | W10: =IFERROR(__xludf.DUMMYFUNCTION("AVERAGE(SORTN(FILTER('Player Values - Cats'!T11:T1004, 'Player Values - Cats'!$D11:$D1004 = $A10, ISNUMBER('Player Values - Cats'!T11:T1004)), $B$1, 0, 1, FALSE))"),0.14109880366818844) -> 0.1410988 | X10: =IFERROR(__xludf.DUMMYFUNCTION("AVERAGE(SORTN(FILTER('Player Values - Cats'!U11:U1004, 'Player Values - Cats'!$D11:$D1004 = $A10, ISNUMBER('Player Values - Cats'!U11:U1004)), $B$1, 0, 1, FALSE))"),1.4581272086588117) -> 1.4581272 | Y10: =IFERROR(__xludf.DUMMYFUNCTION("AVERAGE(SORTN(FILTER('Player Values - Cats'!V11:V1004, 'Player Values - Cats'!$D11:$D1004 = $A10, ISNUMBER('Player Values - Cats'!V11:V1004)), $B$1, 0, 1, FALSE))"),0.832810834601814) -> 0.83281083 | Z10: =IFERROR(__xludf.DUMMYFUNCTION("AVERAGE(SORTN(FILTER('Player Values - Cats'!W11:W1004, 'Player Values - Cats'!$D11:$D1004 = $A10, ISNUMBER('Player Values - Cats'!W11:W1004)), $B$1, 0, 1, FALSE))"),0.9428382122235973) -> 0.94283821 | AA10: =IFERROR(__xludf.DUMMYFUNCTION("AVERAGE(SORTN(FILTER('Player Values - Cats'!X11:X1004, 'Player Values - Cats'!$D11:$D1004 = $A10, ISNUMBER('Player Values - Cats'!X11:X1004)), $B$1, 0, 1, FALSE))"),0.7582815842243424) -> 0.75828158 | AB10: =IFERROR(__xludf.DUMMYFUNCTION("AVERAGE(SORTN(FILTER('Player Values - Cats'!Y11:Y1004, 'Player Values - Cats'!$D11:$D1004 = $A10, ISNUMBER('Player Values - Cats'!Y11:Y1004)), $B$2, 0, 1, FALSE))"),1.8745719704079356) -> 1.874572 | AC10: =IFERROR(__xludf.DUMMYFUNCTION("AVERAGE(SORTN(FILTER('Player Values - Cats'!Z11:Z1004, 'Player Values - Cats'!$D11:$D1004 = $A10, ISNUMBER('Player Values - Cats'!Z11:Z1004)), $B$2, 0, 1, FALSE))"),1.8637553361078611) -> 1.8637553 | AD10: =IFERROR(__xludf.DUMMYFUNCTION("AVERAGE(SORTN(FILTER('Player Values - Cats'!AA11:AA1004, 'Player Values - Cats'!$D11:$D1004 = $A10, ISNUMBER('Player Values - Cats'!AA11:AA1004)), $B$2, 0, 1, FALSE))"),2.1818723268232665) -> 2.1818723 | AE10: =IFERROR(__xludf.DUMMYFUNCTION("AVERAGE(SORTN(FILTER('Player Values - Cats'!AB11:AB1004, 'Player Values - Cats'!$D11:$D1004 = $A10, ISNUMBER('Player Values - Cats'!AB11:AB1004)), $B$2, 0, 1, FALSE))"),0.535423679278133) -> 0.53542368
A11: Jeremy | B11: =AVERAGEIFS('Player Values - Cats'!O:O, 'Player Values - Cats'!$D:$D, $A11, 'Player Values - Cats'!O:O, "<>") -> 0.046310545 | C11: =AVERAGEIFS('Player Values - Cats'!P:P, 'Player Values - Cats'!$D:$D, $A11, 'Player Values - Cats'!P:P, "<>") -> 0.50314841 | D11: =AVERAGEIFS('Player Values - Cats'!Q:Q, 'Player Values - Cats'!$D:$D, $A11, 'Player Values - Cats'!Q:Q, "<>") -> -0.4599141 | E11: =AVERAGEIFS('Player Values - Cats'!R:R, 'Player Values - Cats'!$D:$D, $A11, 'Player Values - Cats'!R:R, "<>") -> -0.86888348 | F11: =AVERAGEIFS('Player Values - Cats'!S:S, 'Player Values - Cats'!$D:$D, $A11, 'Player Values - Cats'!S:S, "<>") -> 0.39518739 | G11: =AVERAGEIFS('Player Values - Cats'!T:T, 'Player Values - Cats'!$D:$D, $A11, 'Player Values - Cats'!T:T, "<>") -> -0.32435971 | H11: =AVERAGEIFS('Player Values - Cats'!U:U, 'Player Values - Cats'!$D:$D, $A11, 'Player Values - Cats'!U:U, "<>") -> 0.19225744 | I11: =AVERAGEIFS('Player Values - Cats'!V:V, 'Player Values - Cats'!$D:$D, $A11, 'Player Values - Cats'!V:V, "<>") -> 0.5448067 | J11: =AVERAGEIFS('Player Values - Cats'!W:W, 'Player Values - Cats'!$D:$D, $A11, 'Player Values - Cats'!W:W, "<>") -> -1.4845607 | K11: =AVERAGEIFS('Player Values - Cats'!X:X, 'Player Values - Cats'!$D:$D, $A11, 'Player Values - Cats'!X:X, "<>") -> -0.82718328 | L11: =AVERAGEIFS('Player Values - Cats'!Y:Y, 'Player Values - Cats'!$D:$D, $A11, 'Player Values - Cats'!Y:Y, "<>") -> -0.41760723 | M11: =AVERAGEIFS('Player Values - Cats'!Z:Z, 'Player Values - Cats'!$D:$D, $A11, 'Player Values - Cats'!Z:Z, "<>") -> 0.23849411 | N11: =AVERAGEIFS('Player Values - Cats'!AA:AA, 'Player Values - Cats'!$D:$D, $A11, 'Player Values - Cats'!AA:AA, "<>") -> -0.072297534 | O11: =AVERAGEIFS('Player Values - Cats'!AB:AB, 'Player Values - Cats'!$D:$D, $A11, 'Player Values - Cats'!AB:AB, "<>") -> 0.23525177 | R11: =IFERROR(__xludf.DUMMYFUNCTION("AVERAGE(SORTN(FILTER('Player Values - Cats'!O12:O1004, 'Player Values - Cats'!$D12:$D1004 = $A11, ISNUMBER('Player Values - Cats'!O12:O1004)), $B$1, 0, 1, FALSE))"),1.343598049679032) -> 1.343598 | S11: =IFERROR(__xludf.DUMMYFUNCTION("AVERAGE(SORTN(FILTER('Player Values - Cats'!P12:P1004, 'Player Values - Cats'!$D12:$D1004 = $A11, ISNUMBER('Player Values - Cats'!P12:P1004)), $B$1, 0, 1, FALSE))"),1.5997366717250514) -> 1.5997367 | T11: =IFERROR(__xludf.DUMMYFUNCTION("AVERAGE(SORTN(FILTER('Player Values - Cats'!Q12:Q1004, 'Player Values - Cats'!$D12:$D1004 = $A11, ISNUMBER('Player Values - Cats'!Q12:Q1004)), $B$1, 0, 1, FALSE))"),0.8252306782312138) -> 0.82523068 | U11: =IFERROR(__xludf.DUMMYFUNCTION("AVERAGE(SORTN(FILTER('Player Values - Cats'!R12:R1004, 'Player Values - Cats'!$D12:$D1004 = $A11, ISNUMBER('Player Values - Cats'!R12:R1004)), $B$1, 0, 1, FALSE))"),0.17984554313443404) -> 0.17984554 | V11: =IFERROR(__xludf.DUMMYFUNCTION("AVERAGE(SORTN(FILTER('Player Values - Cats'!S12:S1004, 'Player Values - Cats'!$D12:$D1004 = $A11, ISNUMBER('Player Values - Cats'!S12:S1004)), $B$1, 0, 1, FALSE))"),1.4044664210129532) -> 1.4044664 | W11: =IFERROR(__xludf.DUMMYFUNCTION("AVERAGE(SORTN(FILTER('Player Values - Cats'!T12:T1004, 'Player Values - Cats'!$D12:$D1004 = $A11, ISNUMBER('Player Values - Cats'!T12:T1004)), $B$1, 0, 1, FALSE))"),0.29250573252604983) -> 0.29250573 | X11: =IFERROR(__xludf.DUMMYFUNCTION("AVERAGE(SORTN(FILTER('Player Values - Cats'!U12:U1004, 'Player Values - Cats'!$D12:$D1004 = $A11, ISNUMBER('Player Values - Cats'!U12:U1004)), $B$1, 0, 1, FALSE))"),1.257007897558005) -> 1.2570079 | Y11: =IFERROR(__xludf.DUMMYFUNCTION("AVERAGE(SORTN(FILTER('Player Values - Cats'!V12:V1004, 'Player Values - Cats'!$D12:$D1004 = $A11, ISNUMBER('Player Values - Cats'!V12:V1004)), $B$1, 0, 1, FALSE))"),1.4709780982106624) -> 1.4709781 | Z11: =IFERROR(__xludf.DUMMYFUNCTION("AVERAGE(SORTN(FILTER('Player Values - Cats'!W12:W1004, 'Player Values - Cats'!$D12:$D1004 = $A11, ISNUMBER('Player Values - Cats'!W12:W1004)), $B$1, 0, 1, FALSE))"),-0.6342569401101408) -> -0.63425694 | AA11: =IFERROR(__xludf.DUMMYFUNCTION("AVERAGE(SORTN(FILTER('Player Values - Cats'!X12:X1004, 'Player Values - Cats'!$D12:$D1004 = $A11, ISNUMBER('Player Values - Cats'!X12:X1004)), $B$1, 0, 1, FALSE))"),0.5642729409566621) -> 0.56427294 | AB11: =IFERROR(__xludf.DUMMYFUNCTION("AVERAGE(SORTN(FILTER('Player Values - Cats'!Y12:Y1004, 'Player Values - Cats'!$D12:$D1004 = $A11, ISNUMBER('Player Values - Cats'!Y12:Y1004)), $B$2, 0, 1, FALSE))"),1.6023352367632702) -> 1.6023352 | AC11: =IFERROR(__xludf.DUMMYFUNCTION("AVERAGE(SORTN(FILTER('Player Values - Cats'!Z12:Z1004, 'Player Values - Cats'!$D12:$D1004 = $A11, ISNUMBER('Player Values - Cats'!Z12:Z1004)), $B$2, 0, 1, FALSE))"),2.32964090577854) -> 2.3296409 | AD11: =IFERROR(__xludf.DUMMYFUNCTION("AVERAGE(SORTN(FILTER('Player Values - Cats'!AA12:AA1004, 'Player Values - Cats'!$D12:$D1004 = $A11, ISNUMBER('Player Values - Cats'!AA12:AA1004)), $B$2, 0, 1, FALSE))"),2.512759645863766) -> 2.5127596 | AE11: =IFERROR(__xludf.DUMMYFUNCTION("AVERAGE(SORTN(FILTER('Player Values - Cats'!AB12:AB1004, 'Player Values - Cats'!$D12:$D1004 = $A11, ISNUMBER('Player Values - Cats'!AB12:AB1004)), $B$2, 0, 1, FALSE))"),0.8223602735388716) -> 0.82236027
A12: Ryan | B12: =AVERAGEIFS('Player Values - Cats'!O:O, 'Player Values - Cats'!$D:$D, $A12, 'Player Values - Cats'!O:O, "<>") -> 0.029709548 | C12: =AVERAGEIFS('Player Values - Cats'!P:P, 'Player Values - Cats'!$D:$D, $A12, 'Player Values - Cats'!P:P, "<>") -> 0.30685265 | D12: =AVERAGEIFS('Player Values - Cats'!Q:Q, 'Player Values - Cats'!$D:$D, $A12, 'Player Values - Cats'!Q:Q, "<>") -> 0.020740509 | E12: =AVERAGEIFS('Player Values - Cats'!R:R, 'Player Values - Cats'!$D:$D, $A12, 'Player Values - Cats'!R:R, "<>") -> -0.5350496 | F12: =AVERAGEIFS('Player Values - Cats'!S:S, 'Player Values - Cats'!$D:$D, $A12, 'Player Values - Cats'!S:S, "<>") -> 0.17198104 | G12: =AVERAGEIFS('Player Values - Cats'!T:T, 'Player Values - Cats'!$D:$D, $A12, 'Player Values - Cats'!T:T, "<>") -> -0.34978229 | H12: =AVERAGEIFS('Player Values - Cats'!U:U, 'Player Values - Cats'!$D:$D, $A12, 'Player Values - Cats'!U:U, "<>") -> 0.11664332 | I12: =AVERAGEIFS('Player Values - Cats'!V:V, 'Player Values - Cats'!$D:$D, $A12, 'Player Values - Cats'!V:V, "<>") -> 0.28713107 | J12: =AVERAGEIFS('Player Values - Cats'!W:W, 'Player Values - Cats'!$D:$D, $A12, 'Player Values - Cats'!W:W, "<>") -> -1.2680456 | K12: =AVERAGEIFS('Player Values - Cats'!X:X, 'Player Values - Cats'!$D:$D, $A12, 'Player Values - Cats'!X:X, "<>") -> -0.93813474 | L12: =AVERAGEIFS('Player Values - Cats'!Y:Y, 'Player Values - Cats'!$D:$D, $A12, 'Player Values - Cats'!Y:Y, "<>") -> 0.59803214 | M12: =AVERAGEIFS('Player Values - Cats'!Z:Z, 'Player Values - Cats'!$D:$D, $A12, 'Player Values - Cats'!Z:Z, "<>") -> -0.71026244 | N12: =AVERAGEIFS('Player Values - Cats'!AA:AA, 'Player Values - Cats'!$D:$D, $A12, 'Player Values - Cats'!AA:AA, "<>") -> -0.59206636 | O12: =AVERAGEIFS('Player Values - Cats'!AB:AB, 'Player Values - Cats'!$D:$D, $A12, 'Player Values - Cats'!AB:AB, "<>") -> 0.33388009 | R12: =IFERROR(__xludf.DUMMYFUNCTION("AVERAGE(SORTN(FILTER('Player Values - Cats'!O13:O1004, 'Player Values - Cats'!$D13:$D1004 = $A12, ISNUMBER('Player Values - Cats'!O13:O1004)), $B$1, 0, 1, FALSE))"),0.9011830409674934) -> 0.90118304 | S12: =IFERROR(__xludf.DUMMYFUNCTION("AVERAGE(SORTN(FILTER('Player Values - Cats'!P13:P1004, 'Player Values - Cats'!$D13:$D1004 = $A12, ISNUMBER('Player Values - Cats'!P13:P1004)), $B$1, 0, 1, FALSE))"),0.9905172125050982) -> 0.99051721 | T12: =IFERROR(__xludf.DUMMYFUNCTION("AVERAGE(SORTN(FILTER('Player Values - Cats'!Q13:Q1004, 'Player Values - Cats'!$D13:$D1004 = $A12, ISNUMBER('Player Values - Cats'!Q13:Q1004)), $B$1, 0, 1, FALSE))"),1.6209116663683574) -> 1.6209117 | U12: =IFERROR(__xludf.DUMMYFUNCTION("AVERAGE(SORTN(FILTER('Player Values - Cats'!R13:R1004, 'Player Values - Cats'!$D13:$D1004 = $A12, ISNUMBER('Player Values - Cats'!R13:R1004)), $B$1, 0, 1, FALSE))"),0.7510268632725864) -> 0.75102686 | V12: =IFERROR(__xludf.DUMMYFUNCTION("AVERAGE(SORTN(FILTER('Player Values - Cats'!S13:S1004, 'Player Values - Cats'!$D13:$D1004 = $A12, ISNUMBER('Player Values - Cats'!S13:S1004)), $B$1, 0, 1, FALSE))"),1.0461016303014405) -> 1.0461016 | W12: =IFERROR(__xludf.DUMMYFUNCTION("AVERAGE(SORTN(FILTER('Player Values - Cats'!T13:T1004, 'Player Values - Cats'!$D13:$D1004 = $A12, ISNUMBER('Player Values - Cats'!T13:T1004)), $B$1, 0, 1, FALSE))"),0.23663792498201403) -> 0.23663792 | X12: =IFERROR(__xludf.DUMMYFUNCTION("AVERAGE(SORTN(FILTER('Player Values - Cats'!U13:U1004, 'Player Values - Cats'!$D13:$D1004 = $A12, ISNUMBER('Player Values - Cats'!U13:U1004)), $B$1, 0, 1, FALSE))"),0.8123769198639351) -> 0.81237692 | Y12: =IFERROR(__xludf.DUMMYFUNCTION("AVERAGE(SORTN(FILTER('Player Values - Cats'!V13:V1004, 'Player Values - Cats'!$D13:$D1004 = $A12, ISNUMBER('Player Values - Cats'!V13:V1004)), $B$1, 0, 1, FALSE))"),0.6323612592696165) -> 0.63236126 | Z12: =IFERROR(__xludf.DUMMYFUNCTION("AVERAGE(SORTN(FILTER('Player Values - Cats'!W13:W1004, 'Player Values - Cats'!$D13:$D1004 = $A12, ISNUMBER('Player Values - Cats'!W13:W1004)), $B$1, 0, 1, FALSE))"),-0.3693986859762793) -> -0.36939869 | AA12: =IFERROR(__xludf.DUMMYFUNCTION("AVERAGE(SORTN(FILTER('Player Values - Cats'!X13:X1004, 'Player Values - Cats'!$D13:$D1004 = $A12, ISNUMBER('Player Values - Cats'!X13:X1004)), $B$1, 0, 1, FALSE))"),0.042855251981348985) -> 0.042855252 | AB12: =IFERROR(__xludf.DUMMYFUNCTION("AVERAGE(SORTN(FILTER('Player Values - Cats'!Y13:Y1004, 'Player Values - Cats'!$D13:$D1004 = $A12, ISNUMBER('Player Values - Cats'!Y13:Y1004)), $B$2, 0, 1, FALSE))"),1.6061551187922931) -> 1.6061551 | AC12: =IFERROR(__xludf.DUMMYFUNCTION("AVERAGE(SORTN(FILTER('Player Values - Cats'!Z13:Z1004, 'Player Values - Cats'!$D13:$D1004 = $A12, ISNUMBER('Player Values - Cats'!Z13:Z1004)), $B$2, 0, 1, FALSE))"),0.6553646397745425) -> 0.65536464 | AD12: =IFERROR(__xludf.DUMMYFUNCTION("AVERAGE(SORTN(FILTER('Player Values - Cats'!AA13:AA1004, 'Player Values - Cats'!$D13:$D1004 = $A12, ISNUMBER('Player Values - Cats'!AA13:AA1004)), $B$2, 0, 1, FALSE))"),1.1340624831950894) -> 1.1340625 | AE12: =IFERROR(__xludf.DUMMYFUNCTION("AVERAGE(SORTN(FILTER('Player Values - Cats'!AB13:AB1004, 'Player Values - Cats'!$D13:$D1004 = $A12, ISNUMBER('Player Values - Cats'!AB13:AB1004)), $B$2, 0, 1, FALSE))"),0.9031903501985471) -> 0.90319035
A13: Harley | B13: =AVERAGEIFS('Player Values - Cats'!O:O, 'Player Values - Cats'!$D:$D, $A13, 'Player Values - Cats'!O:O, "<>") -> 0.19737841 | C13: =AVERAGEIFS('Player Values - Cats'!P:P, 'Player Values - Cats'!$D:$D, $A13, 'Player Values - Cats'!P:P, "<>") -> 0.24171902 | D13: =AVERAGEIFS('Player Values - Cats'!Q:Q, 'Player Values - Cats'!$D:$D, $A13, 'Player Values - Cats'!Q:Q, "<>") -> -0.29146665 | E13: =AVERAGEIFS('Player Values - Cats'!R:R, 'Player Values - Cats'!$D:$D, $A13, 'Player Values - Cats'!R:R, "<>") -> -0.56749528 | F13: =AVERAGEIFS('Player Values - Cats'!S:S, 'Player Values - Cats'!$D:$D, $A13, 'Player Values - Cats'!S:S, "<>") -> 0.25987629 | G13: =AVERAGEIFS('Player Values - Cats'!T:T, 'Player Values - Cats'!$D:$D, $A13, 'Player Values - Cats'!T:T, "<>") -> -0.34604538 | H13: =AVERAGEIFS('Player Values - Cats'!U:U, 'Player Values - Cats'!$D:$D, $A13, 'Player Values - Cats'!U:U, "<>") -> 0.14844738 | I13: =AVERAGEIFS('Player Values - Cats'!V:V, 'Player Values - Cats'!$D:$D, $A13, 'Player Values - Cats'!V:V, "<>") -> 0.27044387 | J13: =AVERAGEIFS('Player Values - Cats'!W:W, 'Player Values - Cats'!$D:$D, $A13, 'Player Values - Cats'!W:W, "<>") -> -0.7576493 | K13: =AVERAGEIFS('Player Values - Cats'!X:X, 'Player Values - Cats'!$D:$D, $A13, 'Player Values - Cats'!X:X, "<>") -> -1.0984194 | L13: =AVERAGEIFS('Player Values - Cats'!Y:Y, 'Player Values - Cats'!$D:$D, $A13, 'Player Values - Cats'!Y:Y, "<>") -> -0.30229463 | M13: =AVERAGEIFS('Player Values - Cats'!Z:Z, 'Player Values - Cats'!$D:$D, $A13, 'Player Values - Cats'!Z:Z, "<>") -> -1.4352969 | N13: =AVERAGEIFS('Player Values - Cats'!AA:AA, 'Player Values - Cats'!$D:$D, $A13, 'Player Values - Cats'!AA:AA, "<>") -> -2.1913551 | O13: =AVERAGEIFS('Player Values - Cats'!AB:AB, 'Player Values - Cats'!$D:$D, $A13, 'Player Values - Cats'!AB:AB, "<>") -> 0.38850153 | R13: =IFERROR(__xludf.DUMMYFUNCTION("AVERAGE(SORTN(FILTER('Player Values - Cats'!O14:O1004, 'Player Values - Cats'!$D14:$D1004 = $A13, ISNUMBER('Player Values - Cats'!O14:O1004)), $B$1, 0, 1, FALSE))"),1.352905838598224) -> 1.3529058 | S13: =IFERROR(__xludf.DUMMYFUNCTION("AVERAGE(SORTN(FILTER('Player Values - Cats'!P14:P1004, 'Player Values - Cats'!$D14:$D1004 = $A13, ISNUMBER('Player Values - Cats'!P14:P1004)), $B$1, 0, 1, FALSE))"),1.3148654371305377) -> 1.3148654 | T13: =IFERROR(__xludf.DUMMYFUNCTION("AVERAGE(SORTN(FILTER('Player Values - Cats'!Q14:Q1004, 'Player Values - Cats'!$D14:$D1004 = $A13, ISNUMBER('Player Values - Cats'!Q14:Q1004)), $B$1, 0, 1, FALSE))"),0.873076844897129) -> 0.87307684 | U13: =IFERROR(__xludf.DUMMYFUNCTION("AVERAGE(SORTN(FILTER('Player Values - Cats'!R14:R1004, 'Player Values - Cats'!$D14:$D1004 = $A13, ISNUMBER('Player Values - Cats'!R14:R1004)), $B$1, 0, 1, FALSE))"),0.17092472318487967) -> 0.17092472 | V13: =IFERROR(__xludf.DUMMYFUNCTION("AVERAGE(SORTN(FILTER('Player Values - Cats'!S14:S1004, 'Player Values - Cats'!$D14:$D1004 = $A13, ISNUMBER('Player Values - Cats'!S14:S1004)), $B$1, 0, 1, FALSE))"),1.2019665219198628) -> 1.2019665 | W13: =IFERROR(__xludf.DUMMYFUNCTION("AVERAGE(SORTN(FILTER('Player Values - Cats'!T14:T1004, 'Player Values - Cats'!$D14:$D1004 = $A13, ISNUMBER('Player Values - Cats'!T14:T1004)), $B$1, 0, 1, FALSE))"),0.33753158455860294) -> 0.33753158 | X13: =IFERROR(__xludf.DUMMYFUNCTION("AVERAGE(SORTN(FILTER('Player Values - Cats'!U14:U1004, 'Player Values - Cats'!$D14:$D1004 = $A13, ISNUMBER('Player Values - Cats'!U14:U1004)), $B$1, 0, 1, FALSE))"),1.1961200108073755) -> 1.19612 | Y13: =IFERROR(__xludf.DUMMYFUNCTION("AVERAGE(SORTN(FILTER('Player Values - Cats'!V14:V1004, 'Player Values - Cats'!$D14:$D1004 = $A13, ISNUMBER('Player Values - Cats'!V14:V1004)), $B$1, 0, 1, FALSE))"),0.703154050316792) -> 0.70315405 | Z13: =IFERROR(__xludf.DUMMYFUNCTION("AVERAGE(SORTN(FILTER('Player Values - Cats'!W14:W1004, 'Player Values - Cats'!$D14:$D1004 = $A13, ISNUMBER('Player Values - Cats'!W14:W1004)), $B$1, 0, 1, FALSE))"),0.7710654148216409) -> 0.77106541 | AA13: =IFERROR(__xludf.DUMMYFUNCTION("AVERAGE(SORTN(FILTER('Player Values - Cats'!X14:X1004, 'Player Values - Cats'!$D14:$D1004 = $A13, ISNUMBER('Player Values - Cats'!X14:X1004)), $B$1, 0, 1, FALSE))"),-0.11642922767200241) -> -0.11642923 | AB13: =IFERROR(__xludf.DUMMYFUNCTION("AVERAGE(SORTN(FILTER('Player Values - Cats'!Y14:Y1004, 'Player Values - Cats'!$D14:$D1004 = $A13, ISNUMBER('Player Values - Cats'!Y14:Y1004)), $B$2, 0, 1, FALSE))"),0.8474553296888792) -> 0.84745533 | AC13: =IFERROR(__xludf.DUMMYFUNCTION("AVERAGE(SORTN(FILTER('Player Values - Cats'!Z14:Z1004, 'Player Values - Cats'!$D14:$D1004 = $A13, ISNUMBER('Player Values - Cats'!Z14:Z1004)), $B$2, 0, 1, FALSE))"),-0.20361187930576785) -> -0.20361188 | AD13: =IFERROR(__xludf.DUMMYFUNCTION("AVERAGE(SORTN(FILTER('Player Values - Cats'!AA14:AA1004, 'Player Values - Cats'!$D14:$D1004 = $A13, ISNUMBER('Player Values - Cats'!AA14:AA1004)), $B$2, 0, 1, FALSE))"),0.9134709371681305) -> 0.91347094 | AE13: =IFERROR(__xludf.DUMMYFUNCTION("AVERAGE(SORTN(FILTER('Player Values - Cats'!AB14:AB1004, 'Player Values - Cats'!$D14:$D1004 = $A13, ISNUMBER('Player Values - Cats'!AB14:AB1004)), $B$2, 0, 1, FALSE))"),1.3806745794623307) -> 1.3806746
A15: Teams | B15: G | C15: A | D15: +/- | E15: PIM | F15: PPP | G15: SHP | H15: SOG | I15: FOW | J15: HIT | K15: BLK | L15: W | M15: GAA | N15: SV% | O15: SO | P15: Avg | R15: =B15 -> G | S15: =C15 -> A | T15: =D15 -> +/- | U15: =E15 -> PIM | V15: =F15 -> PPP | W15: =G15 -> SHP | X15: =H15 -> SOG | Y15: =I15 -> FOW | ... AE15: =O15 -> SO | AF15: Avg
A16: Rob/Orad | B16: =rank(B6,B$6:B$13,False) -> 1 | C16: =rank(C6,C$6:C$13,False) -> 3 | D16: =rank(D6,D$6:D$13,False) -> 3 | E16: =rank(E6,E$6:E$13,False) -> 5 | F16: =rank(F6,F$6:F$13,False) -> 2 | G16: =rank(G6,G$6:G$13,False) -> 2 | H16: =rank(H6,H$6:H$13,False) -> 3 | I16: =rank(I6,I$6:I$13,False) -> 3 | ... O16: =rank(O6,O$6:O$13,False) -> 3 | P16: =AVERAGE(B16:O16) -> 2.4285714 | R16: =rank(R6,R$6:R$13,False) -> 1 | S16: =rank(S6,S$6:S$13,False) -> 4 | T16: =rank(T6,T$6:T$13,False) -> 2 | U16: =rank(U6,U$6:U$13,False) -> 7 | V16: =rank(V6,V$6:V$13,False) -> 1 | W16: =rank(W6,W$6:W$13,False) -> 3 | X16: =rank(X6,X$6:X$13,False) -> 2 | Y16: =rank(Y6,Y$6:Y$13,False) -> 3 | ... AE16: =rank(AE6,AE$6:AE$13,False) -> 4 | AF16: =AVERAGE(R16:AE16) -> 3.2857143
A17: Phil | B17: =rank(B7,B$6:B$13,False) -> 4 | C17: =rank(C7,C$6:C$13,False) -> 5 | D17: =rank(D7,D$6:D$13,False) -> 8 | E17: =rank(E7,E$6:E$13,False) -> 6 | F17: =rank(F7,F$6:F$13,False) -> 3 | G17: =rank(G7,G$6:G$13,False) -> 8 | H17: =rank(H7,H$6:H$13,False) -> 1 | I17: =rank(I7,I$6:I$13,False) -> 2 | ... O17: =rank(O7,O$6:O$13,False) -> 8 | P17: =AVERAGE(B17:O17) -> 4.6428571 | R17: =rank(R7,R$6:R$13,False) -> 2 | S17: =rank(S7,S$6:S$13,False) -> 3 | T17: =rank(T7,T$6:T$13,False) -> 4 | U17: =rank(U7,U$6:U$13,False) -> 6 | V17: =rank(V7,V$6:V$13,False) -> 2 | W17: =rank(W7,W$6:W$13,False) -> 7 | X17: =rank(X7,X$6:X$13,False) -> 1 | Y17: =rank(Y7,Y$6:Y$13,False) -> 2 | ... AE17: =rank(AE7,AE$6:AE$13,False) -> 8 | AF17: =AVERAGE(R17:AE17) -> 4.4285714
A18: Ilan | B18: =rank(B8,B$6:B$13,False) -> 3 | C18: =rank(C8,C$6:C$13,False) -> 4 | D18: =rank(D8,D$6:D$13,False) -> 6 | E18: =rank(E8,E$6:E$13,False) -> 1 | F18: =rank(F8,F$6:F$13,False) -> 5 | G18: =rank(G8,G$6:G$13,False) -> 1 | H18: =rank(H8,H$6:H$13,False) -> 2 | I18: =rank(I8,I$6:I$13,False) -> 4 | ... O18: =rank(O8,O$6:O$13,False) -> 5 | P18: =AVERAGE(B18:O18) -> 3.9285714 | R18: =rank(R8,R$6:R$13,False) -> 5 | S18: =rank(S8,S$6:S$13,False) -> 2 | T18: =rank(T8,T$6:T$13,False) -> 7 | U18: =rank(U8,U$6:U$13,False) -> 3 | V18: =rank(V8,V$6:V$13,False) -> 4 | W18: =rank(W8,W$6:W$13,False) -> 4 | X18: =rank(X8,X$6:X$13,False) -> 5 | Y18: =rank(Y8,Y$6:Y$13,False) -> 4 | ... AE18: =rank(AE8,AE$6:AE$13,False) -> 6 | AF18: =AVERAGE(R18:AE18) -> 5
A19: Lev | B19: =rank(B9,B$6:B$13,False) -> 2 | C19: =rank(C9,C$6:C$13,False) -> 1 | D19: =rank(D9,D$6:D$13,False) -> 2 | E19: =rank(E9,E$6:E$13,False) -> 7 | F19: =rank(F9,F$6:F$13,False) -> 1 | G19: =rank(G9,G$6:G$13,False) -> 3 | H19: =rank(H9,H$6:H$13,False) -> 5 | I19: =rank(I9,I$6:I$13,False) -> 5 | ... O19: =rank(O9,O$6:O$13,False) -> 7 | P19: =AVERAGE(B19:O19) -> 4 | R19: =rank(R9,R$6:R$13,False) -> 7 | S19: =rank(S9,S$6:S$13,False) -> 6 | T19: =rank(T9,T$6:T$13,False) -> 3 | U19: =rank(U9,U$6:U$13,False) -> 8 | V19: =rank(V9,V$6:V$13,False) -> 6 | W19: =rank(W9,W$6:W$13,False) -> 1 | X19: =rank(X9,X$6:X$13,False) -> 7 | Y19: =rank(Y9,Y$6:Y$13,False) -> 6 | ... AE19: =rank(AE9,AE$6:AE$13,False) -> 7 | AF19: =AVERAGE(R19:AE19) -> 4.7857143
A20: Henry | B20: =rank(B10,B$6:B$13,False) -> 6 | C20: =rank(C10,C$6:C$13,False) -> 8 | D20: =rank(D10,D$6:D$13,False) -> 7 | E20: =rank(E10,E$6:E$13,False) -> 2 | F20: =rank(F10,F$6:F$13,False) -> 8 | G20: =rank(G10,G$6:G$13,False) -> 4 | H20: =rank(H10,H$6:H$13,False) -> 4 | I20: =rank(I10,I$6:I$13,False) -> 6 | ... O20: =rank(O10,O$6:O$13,False) -> 6 | P20: =AVERAGE(B20:O20) -> 5.1428571 | R20: =rank(R10,R$6:R$13,False) -> 6 | S20: =rank(S10,S$6:S$13,False) -> 8 | T20: =rank(T10,T$6:T$13,False) -> 8 | U20: =rank(U10,U$6:U$13,False) -> 1 | V20: =rank(V10,V$6:V$13,False) -> 8 | W20: =rank(W10,W$6:W$13,False) -> 8 | X20: =rank(X10,X$6:X$13,False) -> 3 | Y20: =rank(Y10,Y$6:Y$13,False) -> 5 | ... AE20: =rank(AE10,AE$6:AE$13,False) -> 5 | AF20: =AVERAGE(R20:AE20) -> 4.3571429
A21: Jeremy | B21: =rank(B11,B$6:B$13,False) -> 7 | C21: =rank(C11,C$6:C$13,False) -> 2 | D21: =rank(D11,D$6:D$13,False) -> 5 | E21: =rank(E11,E$6:E$13,False) -> 8 | F21: =rank(F11,F$6:F$13,False) -> 4 | G21: =rank(G11,G$6:G$13,False) -> 5 | H21: =rank(H11,H$6:H$13,False) -> 6 | I21: =rank(I11,I$6:I$13,False) -> 1 | ... O21: =rank(O11,O$6:O$13,False) -> 4 | P21: =AVERAGE(B21:O21) -> 4.9285714 | R21: =rank(R11,R$6:R$13,False) -> 4 | S21: =rank(S11,S$6:S$13,False) -> 1 | T21: =rank(T11,T$6:T$13,False) -> 6 | U21: =rank(U11,U$6:U$13,False) -> 4 | V21: =rank(V11,V$6:V$13,False) -> 3 | W21: =rank(W11,W$6:W$13,False) -> 5 | X21: =rank(X11,X$6:X$13,False) -> 4 | Y21: =rank(Y11,Y$6:Y$13,False) -> 1 | ... AE21: =rank(AE11,AE$6:AE$13,False) -> 3 | AF21: =AVERAGE(R21:AE21) -> 3.6428571
A22: Ryan | B22: =rank(B12,B$6:B$13,False) -> 8 | C22: =rank(C12,C$6:C$13,False) -> 6 | D22: =rank(D12,D$6:D$13,False) -> 1 | E22: =rank(E12,E$6:E$13,False) -> 3 | F22: =rank(F12,F$6:F$13,False) -> 7 | G22: =rank(G12,G$6:G$13,False) -> 7 | H22: =rank(H12,H$6:H$13,False) -> 8 | I22: =rank(I12,I$6:I$13,False) -> 7 | ... O22: =rank(O12,O$6:O$13,False) -> 2 | P22: =AVERAGE(B22:O22) -> 5.2857143 | R22: =rank(R12,R$6:R$13,False) -> 8 | S22: =rank(S12,S$6:S$13,False) -> 7 | T22: =rank(T12,T$6:T$13,False) -> 1 | U22: =rank(U12,U$6:U$13,False) -> 2 | V22: =rank(V12,V$6:V$13,False) -> 7 | W22: =rank(W12,W$6:W$13,False) -> 6 | X22: =rank(X12,X$6:X$13,False) -> 8 | Y22: =rank(Y12,Y$6:Y$13,False) -> 8 | ... AE22: =rank(AE12,AE$6:AE$13,False) -> 2 | AF22: =AVERAGE(R22:AE22) -> 5.3571429
A23: Harley | B23: =rank(B13,B$6:B$13,False) -> 5 | C23: =rank(C13,C$6:C$13,False) -> 7 | D23: =rank(D13,D$6:D$13,False) -> 4 | E23: =rank(E13,E$6:E$13,False) -> 4 | F23: =rank(F13,F$6:F$13,False) -> 6 | G23: =rank(G13,G$6:G$13,False) -> 6 | H23: =rank(H13,H$6:H$13,False) -> 7 | I23: =rank(I13,I$6:I$13,False) -> 8 | ... O23: =rank(O13,O$6:O$13,False) -> 1 | P23: =AVERAGE(B23:O23) -> 5.6428571 | R23: =rank(R13,R$6:R$13,False) -> 3 | S23: =rank(S13,S$6:S$13,False) -> 5 | T23: =rank(T13,T$6:T$13,False) -> 5 | U23: =rank(U13,U$6:U$13,False) -> 5 | V23: =rank(V13,V$6:V$13,False) -> 5 | W23: =rank(W13,W$6:W$13,False) -> 2 | X23: =rank(X13,X$6:X$13,False) -> 6 | Y23: =rank(Y13,Y$6:Y$13,False) -> 7 | ... AE23: =rank(AE13,AE$6:AE$13,False) -> 1 | AF23: =AVERAGE(R23:AE23) -> 5.0714286
A25: Head-to-head
A26: Teams | B26: G | C26: A | D26: +/- | E26: PIM | F26: PPP | G26: SHP | H26: SOG | I26: FOW | J26: HIT | K26: BLK | L26: W | M26: GAA | N26: SV% | O26: SO | P26: Need
A27: Phil | B27: =B$6-B7 -> 0.12297002 | C27: =C$6-C7 -> 0.099201574 | D27: =D$6-D7 -> 0.6760526 | E27: =E$6-E7 -> 0.13257206 | F27: =F$6-F7 -> 0.038356394 | G27: =G$6-G7 -> 0.091609629 | H27: =H$6-H7 -> -0.11973578 | I27: =I$6-I7 -> -0.086006499 | ... O27: =O$6-O7 -> 0.24232779 | P27: =IFERROR(__xludf.DUMMYFUNCTION("IFERROR(TEXTJOIN("", "", TRUE, QUERY(TRANSPOSE({$B$26:$O$26; B27:O27}), ""SELECT Col1 WHERE Col2 <= 0.05 AND Col2 IS NOT NULL ORDER BY Col2 DESC"", 0)), """")"),"PPP, BLK, FOW, SOG") -> PPP, BLK, FOW, SOG
A28: Ilan | B28: =B$6-B8 -> 0.12062973 | C28: =C$6-C8 -> 0.029136536 | D28: =D$6-D8 -> 0.24393966 | E28: =E$6-E8 -> -0.3208539 | F28: =F$6-F8 -> 0.21594841 | G28: =G$6-G8 -> -0.013917601 | H28: =H$6-H8 -> -0.020145739 | I28: =I$6-I8 -> 0.023679614 | ... O28: =O$6-O8 -> 0.083154508 | P28: =IFERROR(__xludf.DUMMYFUNCTION("IFERROR(TEXTJOIN("", "", TRUE, QUERY(TRANSPOSE({$B$26:$O$26; B28:O28}), ""SELECT Col1 WHERE Col2 <= 0.05 AND Col2 IS NOT NULL ORDER BY Col2 DESC"", 0)), """")"),"A, FOW, HIT, SHP, SOG, PIM") -> A, FOW, HIT, SHP, SOG, PIM
A29: Lev | B29: =B$6-B9 -> 0.10649396 | C29: =C$6-C9 -> -0.087770876 | D29: =D$6-D9 -> -0.013551071 | E29: =E$6-E9 -> 0.19211152 | F29: =F$6-F9 -> -0.022096117 | G29: =G$6-G9 -> 0.027877158 | H29: =H$6-H9 -> 0.17261956 | I29: =I$6-I9 -> 0.057634817 | ... O29: =O$6-O9 -> 0.15521528 | P29: =IFERROR(__xludf.DUMMYFUNCTION("IFERROR(TEXTJOIN("", "", TRUE, QUERY(TRANSPOSE({$B$26:$O$26; B29:O29}), ""SELECT Col1 WHERE Col2 <= 0.05 AND Col2 IS NOT NULL ORDER BY Col2 DESC"", 0)), """")"),"SHP, +/-, PPP, A") -> SHP, +/-, PPP, A
A30: Henry | B30: =B$6-B10 -> 0.26442346 | C30: =C$6-C10 -> 0.37605726 | D30: =D$6-D10 -> 0.32585534 | E30: =E$6-E10 -> -0.14454825 | F30: =F$6-F10 -> 0.51521958 | G30: =G$6-G10 -> 0.037615125 | H30: =H$6-H10 -> 0.064858301 | I30: =I$6-I10 -> 0.13103126 | ... O30: =O$6-O10 -> 0.15379922 | P30: =IFERROR(__xludf.DUMMYFUNCTION("IFERROR(TEXTJOIN("", "", TRUE, QUERY(TRANSPOSE({$B$26:$O$26; B30:O30}), ""SELECT Col1 WHERE Col2 <= 0.05 AND Col2 IS NOT NULL ORDER BY Col2 DESC"", 0)), """")"),"SHP, PIM, HIT") -> SHP, PIM, HIT
A31: Jeremy | B31: =B$6-B11 -> 0.28164145 | C31: =C$6-C11 -> -0.051823448 | D31: =D$6-D11 -> 0.24018423 | E31: =E$6-E11 -> 0.20634404 | F31: =F$6-F11 -> 0.09719465 | G31: =G$6-G11 -> 0.040923386 | H31: =H$6-H11 -> 0.22976335 | I31: =I$6-I11 -> -0.095562242 | ... O31: =O$6-O11 -> 0.05240337 | P31: =IFERROR(__xludf.DUMMYFUNCTION("IFERROR(TEXTJOIN("", "", TRUE, QUERY(TRANSPOSE({$B$26:$O$26; B31:O31}), ""SELECT Col1 WHERE Col2 <= 0.05 AND Col2 IS NOT NULL ORDER BY Col2 DESC"", 0)), """")"),"SHP, A, FOW") -> SHP, A, FOW
A32: Ryan | B32: =B$6-B12 -> 0.29824245 | C32: =C$6-C12 -> 0.14447231 | D32: =D$6-D12 -> -0.24047037 | E32: =E$6-E12 -> -0.12748984 | F32: =F$6-F12 -> 0.32040101 | G32: =G$6-G12 -> 0.066345962 | H32: =H$6-H12 -> 0.30537747 | I32: =I$6-I12 -> 0.16211339 | ... O32: =O$6-O12 -> -0.046224946 | P32: =IFERROR(__xludf.DUMMYFUNCTION("IFERROR(TEXTJOIN("", "", TRUE, QUERY(TRANSPOSE({$B$26:$O$26; B32:O32}), ""SELECT Col1 WHERE Col2 <= 0.05 AND Col2 IS NOT NULL ORDER BY Col2 DESC"", 0)), """")"),"SO, PIM, +/-, W") -> SO, PIM, +/-, W
A33: Harley | B33: =B$6-B13 -> 0.13057358 | C33: =C$6-C13 -> 0.20960595 | D33: =D$6-D13 -> 0.071736785 | E33: =E$6-E13 -> -0.095044155 | F33: =F$6-F13 -> 0.23250576 | G33: =G$6-G13 -> 0.062609059 | H33: =H$6-H13 -> 0.27357341 | I33: =I$6-I13 -> 0.1788006 | ... O33: =O$6-O13 -> -0.10084639 | P33: =IFERROR(__xludf.DUMMYFUNCTION("IFERROR(TEXTJOIN("", "", TRUE, QUERY(TRANSPOSE({$B$26:$O$26; B33:O33}), ""SELECT Col1 WHERE Col2 <= 0.05 AND Col2 IS NOT NULL ORDER BY Col2 DESC"", 0)), """")"),"PIM, SO, HIT") -> PIM, SO, HIT

Sheet Player Values - Cats
O1: 1 | P1: 1 | Q1: 1 | R1: 1 | S1: 1 | T1: 0.5 | U1: 1 | V1: 1 | W1: 1 | X1: 1 | Y1: 1 | Z1: 1 | AA1: 1 | AB1: 0.5 | AC1: =if(AC2="","",vlookup(AC2,CatWeights,2,false)) | AD1: =if(AD2="","",vlookup(AD2,CatWeights,2,false)) | AE1: =if(AE2="","",vlookup(AE2,CatWeights,2,false)) | AF1: =if(AF2="","",vlookup(AF2,CatWeights,2,false)) | AG1: =if(AG2="","",vlookup(AG2,CatWeights,2,false)) | AH1: =if(AH2="","",vlookup(AH2,CatWeights,2,false)) | AI1: =if(AI2="","",vlookup(AI2,CatWeights,2,false)) | AJ1: =if(AJ2="","",vlookup(AJ2,CatWeights,2,false)) | ... AN1: =if(AN2="","",vlookup(AN2,CatWeights,2,false))
A2: New ranking | B2: ⭐ | C2: TAKEN | D2: FTeam | E2: PLAYER | F2: TEAM | G2: POS | H2: VAL | I2: VORP | J2: PRNK | K2: Age | L2: GP | M2: OFF | N2: POG | O2: G | P2: A | Q2: +/- | R2: PIM | S2: PPP | T2: SHP | U2: SOG | V2: FOW | W2: HIT | X2: BLK | Y2: W | Z2: GAA | AA2: SV% | AB2: SO | AQ2: NHL_PLAYER_ID
